Workbook
Name Radc: HMI!$U$19

Sheet HMI
B2: LIMITS | E2: Gate Driver | H2: MOSFET | K2: Rboot,ext | N2: Rv2 & Rtrace
B3: Version: | E3: Infineon 2EDL8024 | H3: Reference: | K3: Input data: | N3: Input data:
B4: V1.0 | E4: Input data: | H4: TI CSD18540Q5B | K4: Rshunt (µΩ) | L4: 850 | N4: Rv2 name | O4: 1kΩ, 2012m
B5: =DB_limits[[#Headers],[Frame size (")]] -> Frame size (") | C5: =_xlfn.XLOOKUP($B$4, DB_limits[Name], DB_limits[Frame size (")]) -> 6 | E5: Vdd (V) | F5: 10.5 | H5: =DB_Mostfet[[#Headers],[Vds (V)]] -> Vds (V) | I5: =_xlfn.XLOOKUP(H4, DB_Mostfet[Part], DB_Mostfet[Vds (V)]) -> 60 | N5: =DB_R[[#Headers],[Prated@70°C (W)]] -> Prated@70°C (W) | O5: =_xlfn.XLOOKUP(O4, DB_R[Description], DB_R[Prated@70°C (W)]) -> 0.25
B6: =DB_limits[[#Headers],[Dmax (%)]] -> Dmax (%) | C6: =_xlfn.XLOOKUP($B$4, DB_limits[Name], DB_limits[Dmax (%)]) -> 90 | H6: =DB_Mostfet[[#Headers],[Qg,typ @ 10V (nC)]] -> Qg,typ @ 10V (nC) | I6: =_xlfn.XLOOKUP(H4, DB_Mostfet[Part], DB_Mostfet[Qg,typ @ 10V (nC)]) -> 41 | K6: ADC/OpAmp Isense | N6: Radc,ext name | O6: 33Ω, 2012m
B7: =DB_limits[[#Headers],[Fmax (kHz)]] -> Fmax (kHz) | C7: =_xlfn.XLOOKUP(B4,DB_limits[Name],DB_limits[Fmax (kHz)]) -> 64 | E7: Diode - Dboot | H7: =DB_Mostfet[[#Headers],[Qg,typ,sync @ 10V (nC)]] & " (not used)" -> Qg,typ,sync @ 10V (nC) (not used) | I7: =_xlfn.XLOOKUP(H4, DB_Mostfet[Part], DB_Mostfet[Qg,typ,sync @ 10V (nC)]) -> X | K7: Chose the part: | N7: =N5 -> Prated@70°C (W) | O7: =_xlfn.XLOOKUP(O4, DB_R[Description], DB_R[Prated@70°C (W)]) -> 0.25
B8: =DB_limits[[#Headers],[Vbat,min (V)]] -> Vbat,min (V) | C8: =_xlfn.XLOOKUP($B$4, DB_limits[Name], DB_limits[Vbat,min (V)]) -> 14 | E8: Rohm RB161QS-40 | H8: =DB_Mostfet[[#Headers],[Rds,on@10V typ(mΩ)]] & " (not used)" -> Rds,on@10V typ(mΩ) (not used) | I8: =_xlfn.XLOOKUP(H4, DB_Mostfet[Part], DB_Mostfet[Rds,on@10V typ(mΩ)]) -> 1.8 | K8: STM32G4 internal
B9: =DB_limits[[#Headers],[Vbat,typ (V)]] -> Vbat,typ (V) | C9: =_xlfn.XLOOKUP($B$4, DB_limits[Name], DB_limits[Vbat,typ (V)]) -> 25.2 | H9: =DB_Mostfet[[#Headers],[Rds,on@10V max (mΩ)]] -> Rds,on@10V max (mΩ) | I9: =_xlfn.XLOOKUP(H4, DB_Mostfet[Part], DB_Mostfet[Rds,on@10V max (mΩ)]) -> 2.2 | K9: =DB_ADC[[#Headers],[Vmax (V)]] -> Vmax (V) | L9: =_xlfn.XLOOKUP($K$8, DB_ADC[Name], DB_ADC[Vmax (V)]) -> 3.6 | N9: ADC Isense
B10: =DB_limits[[#Headers],[Vbat spike (V) @ run]] -> Vbat spike (V) @ run | C10: =_xlfn.XLOOKUP($B$4, DB_limits[Name], DB_limits[Vbat spike (V) @ run]) -> 32 | E10: Rpull-down,gate | H10: =DB_Mostfet[[#Headers],[Id @ Tc>70°C (A)]] -> Id @ Tc>70°C (A) | I10: =_xlfn.XLOOKUP(H4, DB_Mostfet[Part], DB_Mostfet[Id @ Tc>70°C (A)]) -> 100 | K10: Input data: | N10: Chose the part:
B11: =DB_limits[[#Headers],[Vbat spike (V) @ disarm]] -> Vbat spike (V) @ disarm | C11: =_xlfn.XLOOKUP($B$4, DB_limits[Name], DB_limits[Vbat spike (V) @ disarm]) -> 45 | E11: Input data: | H11: =DB_Mostfet[[#Headers],[Id @ Ta>70°C (A)]] -> Id @ Ta>70°C (A) | I11: =_xlfn.XLOOKUP(H4, DB_Mostfet[Part], DB_Mostfet[Id @ Ta>70°C (A)]) -> (est ~21A) | K11: Resolution (bit) | L11: 12 | N11: STM32G4 internal
B12: =DB_limits[[#Headers],[Vph spike (V) @ run]] -> Vph spike (V) @ run | C12: =_xlfn.XLOOKUP($B$4, DB_limits[Name], DB_limits[Vph spike (V) @ run]) -> 35 | E12: Rpd,gate (kΩ) | F12: 10 | H12: =DB_Mostfet[[#Headers],[Size (mm)]] -> Size (mm) | I12: =_xlfn.XLOOKUP(H4, DB_Mostfet[Part], DB_Mostfet[Size (mm)]) -> 5x6 | K12: Nsamp (cycle) | L12: 2.5 | N12: =DB_ADC[[#Headers],[Csamp (pF)]] -> Csamp (pF) | O12: =_xlfn.XLOOKUP($N$11, DB_ADC[Name], DB_ADC[Csamp (pF)]) -> 5
B13: =DB_limits[[#Headers],[Vph spike (V) @ disarm]] -> Vph spike (V) @ disarm | C13: =_xlfn.XLOOKUP($B$4, DB_limits[Name], DB_limits[Vph spike (V) @ disarm]) -> 28 | H13: =DB_Mostfet[[#Headers],[JLCPBC stock]] -> JLCPBC stock | I13: =_xlfn.XLOOKUP(H4, DB_Mostfet[Part], DB_Mostfet[JLCPBC stock]) -> Yes | K13: OpAmp gain | L13: 64 | N13: =DB_ADC[[#Headers],[Cpad (pF)]] -> Cpad (pF) | O13: =_xlfn.XLOOKUP($N$11, DB_ADC[Name], DB_ADC[Cpad (pF)]) -> 5
B14: =DB_limits[[#Headers],[Iph typ (A)]] & " @ " & _xlfn.XLOOKUP($B$4, DB_limits[Name], DB_limits[ToF Iph typ (%)]) & "% ToF" -> Iph typ (A) @ 95% ToF | C14: =_xlfn.XLOOKUP($B$4, DB_limits[Name], DB_limits[Iph typ (A)]) -> 12.5 | E14: Cboot & Rboot,ext | H14: Computed data: | K14: Computed data: | N14: Input data:
B15: =DB_limits[[#Headers],[Iph max (A@Xs)]] & " @ " & _xlfn.XLOOKUP($B$4, DB_limits[Name], DB_limits[ToF Iph max (%)]) & "% ToF" -> Iph max (A@Xs) @ 4.9% ToF | C15: =_xlfn.XLOOKUP($B$4, DB_limits[Name], DB_limits[Iph max (A@Xs)]) -> 20 | E15: Input data: | H15: =CAL_Fets!G28 -> Ptot,typ (mW) | I15: =CAL_Fets!H28 -> 1667.2221 | K15: ADC conversion time (ns) | L15: =(L11+L12+0.5)*_xlfn.XLOOKUP(K8,DB_ADC[Name],DB_ADC[Tadc,clock (ns)]) -> 250 | N15: Resolution (bit) | O15: 8
B16: =DB_limits[[#Headers],[Iph spike (A@Xms)]] & " @ " & _xlfn.XLOOKUP($B$4, DB_limits[Name], DB_limits[ToF Iph spike (%)]) & "% ToF" -> Iph spike (A@Xms) @ 0.1% ToF | C16: =_xlfn.XLOOKUP($B$4, DB_limits[Name], DB_limits[Iph spike (A@Xms)]) -> 50 | E16: Expected derating max (%) | F16: 60 | H16: =CAL_Fets!G29 -> Ptot,max (mW) | I16: =CAL_Fets!H29 -> 3145.7629 | K16: =CAL_Rshunt!G22 -> Vshunt,amp,spike (V) | L16: =CAL_Rshunt!H22 -> 2.72 | N16: Nsamp (cycle) | O16: 2.5
B17: =DB_limits[[#Headers],[Iph mean (A)]] -> Iph mean (A) | C17: =_xlfn.XLOOKUP($B$4, DB_limits[Name], DB_limits[Iph mean (A)]) -> 12.905 | E17: Expected derating min (%) | F17: 30 | K17: =CAL_Rshunt!J6 -> ΔIlsb (mA/bit) | L17: =CAL_Rshunt!K6 -> 14.813618 | N17: Ctrace,est (pF) | O17: 5
B18: =DB_limits[[#Headers],[Termistors]] -> Termistors | C18: =_xlfn.XLOOKUP($B$4, DB_limits[Name], DB_limits[Termistors]) -> 3 (one at each FET) | E18: Safety margin on Cboot | F18: 3 | K18: =CAL_Rshunt!J14 -> Pshunt,mean (mW) | L18: =CAL_Rshunt!K14 -> 84.934903 | N18: Computed data:
B19: Input data: | E19: Rboot,ext (Ω) | F19: 3.3 | K19: =CAL_Rshunt!J22 -> Pshunt,max (mW@Xs) | L19: =CAL_Rshunt!K22 -> 204 | N19: ADC conversion time (ns) | O19: =(O15+O16+0.5)*_xlfn.XLOOKUP(N11,DB_ADC[Name],DB_ADC[Tadc,clock (ns)]) -> 183.33333
B20: Min blank time (ns) | C20: 480 | E20: Computed data: | N20: ='CAL_Rv1-2'!G5 -> Rv1,th (Ω) | O20: ='CAL_Rv1-2'!H5 -> 9606.0606
B21: t_blank@V_sw=0 (ns) | C21: 300 | E21: =CAL_Cboot!G12 -> Vboot,min (V) | F21: =CAL_Cboot!H12 -> 6.74 | N21: ='CAL_Rv1-2'!G6 -> Rv1 (Ω) | O21: ='CAL_Rv1-2'!H6 -> 10000
E22: =CAL_Cboot!G18 -> Vboot,max (V) | F22: =CAL_Cboot!H18 -> 10.26 | N22: ='CAL_Rv1-2'!G24 -> Vdivider,typ (V) | O22: ='CAL_Rv1-2'!H24 -> 2.2909091
E23: =CAL_Cboot!M4 -> Cboot,th (nF) | F23: =CAL_Cboot!N4 -> 167.44099 | N23: ='CAL_Rv1-2'!J5 -> Idivider,typ (mA) | O23: ='CAL_Rv1-2'!K5 -> 2.2909091
E24: =CAL_Cboot!M5 -> Cboot (nF) | F24: =CAL_Cboot!N5 -> 180 | N24: ='CAL_Rv1-2'!J25 -> ΔVlsb,fullscale (mV/bit) | O24: ='CAL_Rv1-2'!K25 -> 142.35294
E25: =CAL_Cboot!P23 -> Prboot (mW) | F25: =CAL_Cboot!Q23 -> 49.417753 | N25: ='CAL_Rv1-2'!G14 -> Prv1,rv2 (mW) | O25: ='CAL_Rv1-2'!H14 -> 111.36364
E26: =CAL_Cboot!M13 -> t_recharge (µs) | F26: =CAL_Cboot!N13 -> 1.2625
E27: =CAL_Cboot!P8 -> Vboot,max@Dmax (V) | F27: =CAL_Cboot!Q8 -> 10.255158 | N27: Cadc,ext
N28: Input data:
E29: Gate resistors | N29: Cadc,ext (pF) | O29: 100
E30: Input data: | N30: Expected derating (%) | O30: 40
E31: Rg,on+off (Ω) | F31: 3.3 | N31: Charge factor (int) | O31: 12
E32: Rg,off (Ω) | F32: 10 | N32: Charge factor (ext) | O32: 5
E33: Safety margin on losses | F33: 1.5 | N33: Computed data:
E34: Computed data: | N34: ='CAL_Rv1-2'!M22 -> Cadc,ext,real (pF) | O34: ='CAL_Rv1-2'!N22 -> 60
E35: =CAL_Rg!J5 -> Ig,max,on (A) | F35: =CAL_Rg!K5 -> 1.7389831 | N35: ='CAL_Rv1-2'!M30 -> Tfill,adc,ext (ns) | O35: ='CAL_Rv1-2'!N30 -> 282.62727
E36: =CAL_Rg!J6 -> Ig,max,off (A) | F36: =CAL_Rg!K6 -> 2.2768615 | N36: ='CAL_Rv1-2'!P13 -> Tfill,samp (ns) | O36: ='CAL_Rv1-2'!Q13 -> 169.57636
E37: =CAL_Rg!J25 -> t_rise (ns) | F37: =CAL_Rg!K25 -> 9.8825 | N37: Radc,int < Rain as we use an external capaciot
E38: =CAL_Rg!J26 -> t_fall (ns) | F38: =CAL_Rg!K26 -> 7.54789 | N38: Tfillsam just give a rought too conservative approx
E39: =CAL_Rg!M11 -> Pg,loss (mW) | F39: =CAL_Rg!N11 -> 40.38336
E40: =CAL_Rg!P13 -> Prg,on+off (mW) | F40: =CAL_Rg!Q13 -> 27.360304
E41: =CAL_Rg!P20 -> Prg,off (mW) | F41: =CAL_Rg!Q20 -> 3.8750646
...

Sheet CAL_Cboot
G2: =C13 -> Vdd (V) | H2: =D13 -> 10.5 | J2: =C30 -> Qg,typ @ 10V (nC) | K2: =D30 -> 41 | M2: =C20 -> Safety margin on Cboot | N2: =D20 -> 3 | P2: =G18 -> Vboot,max (V) | Q2: =H18 -> 10.26
C3: LIMITS | G3: =C11 -> Vhbr (V) | H3: =D11 -> 6 | J3: =C14 -> Ihb (mA) | K3: =D14 -> 0.7 | M3: =C18 -> Expected derating max (%) | N3: =D18 -> 60 | P3: =G12 -> Vboot,min (V) | Q3: =H12 -> 6.74
C4: Name | D4: =HMI!B4 -> V1.0 | G4: =C12 -> Vhbh,max (V) | H4: =D12 -> 0.5 | J4: =C15 -> Ihbs (mA) | K4: =D15 -> 1.25 | M4: Cboot,th (nF) | N4: =K15/(1-N3%)*N2 -> 167.44099 | P4: =M13 -> t_recharge (µs) | Q4: =N13 -> 1.2625
C5: =HMI!B6 -> Dmax (%) | D5: =_xlfn.XLOOKUP(D4, DB_limits[Name], DB_limits[Dmax (%)]) -> 90 | G5: Vf (V) | H5: =D23 -> 0.24 | J5: =G24 -> Ipd (mA) | K5: =H24 -> 1.026 | M5: Cboot (nF) | N5: =_xlfn.MINIFS(J21:J32,J21:J32,">="&N4) -> 180 | P5: =M20 -> Req (Ω) | Q5: =N20 -> 2.8608871
C6: =HMI!B7 -> Fmax (kHz) | D6: =_xlfn.XLOOKUP(D4,DB_limits[Name],DB_limits[Fmax (kHz)]) -> 64 | G6: ΔVboot,max (V) | H6: =H2-H3-H4-H5 -> 3.76 | J6: =C5 -> Dmax (%) | K6: =D5 -> 90 | P6: =M5 -> Cboot (nF) | Q6: =N4 -> 167.44099
C7: =HMI!B21 -> t_blank@V_sw=0 (ns) | D7: =HMI!C21 -> 300 | J7: =C6 -> Fmax (kHz) | K7: =D6 -> 64 | P7: =C18 -> Expected derating max (%) | Q7: =D18 -> 60
C8: GD | J8: Qbs (nC) | K8: =K2+(K3+(K4+K5)*K6%)/K7*10^3 -> 83.94375 | P8: Vboot,max@Dmax (V) | Q8: =Q2-(Q2-Q3)*EXP(-Q4/Q5/Q6/(1-Q7%)*10^3) -> 10.255158
C9: Ref | D9: =HMI!E3 -> Infineon 2EDL8024
C10: Vfint,100mA (V) | D10: =_xlfn.XLOOKUP(D9, DB_GD[Part], DB_GD[Vfint,100mA (V)]) -> 2.15 | G10: =G2 -> Vdd (V) | H10: =H2 -> 10.5 | M10: =J6 -> Dmax (%) | N10: =K6 -> 90
C11: Vhbr (V) | D11: =_xlfn.XLOOKUP(D9, DB_GD[Part], DB_GD[Vhbr (V)]) -> 6 | G11: =G6 -> ΔVboot,max (V) | H11: =H6 -> 3.76 | M11: =J7 -> Fmax (kHz) | N11: =K7 -> 64
C12: =DB_GD[[#Headers],[Vhbh,max (V)]] -> Vhbh,max (V) | D12: =_xlfn.XLOOKUP(D9, DB_GD[Part], DB_GD[Vhbh,max (V)]) -> 0.5 | G12: Vboot,min (V) | H12: =H10-H11 -> 6.74 | M12: =C7 -> t_blank@V_sw=0 (ns) | N12: =D7 -> 300 | P12: =M5 -> Cboot (nF) | Q12: =N5 -> 180
C13: =HMI!E5 -> Vdd (V) | D13: =HMI!F5 -> 10.5 | J13: =J8 -> Qbs (nC) | K13: =K8 -> 83.94375 | M13: t_recharge (µs) | N13: =((1-N10%)/N11)*1000-N12/1000 -> 1.2625 | P13: =C19 -> Expected derating min (%) | Q13: =D19 -> 30
C14: =DB_GD[[#Headers],[Ihb (mA)]] -> Ihb (mA) | D14: =_xlfn.XLOOKUP(D9, DB_GD[Part], DB_GD[Ihb (mA)]) -> 0.7 | J14: =G6 -> ΔVboot,max (V) | K14: =H6 -> 3.76 | P14: =G6 -> ΔVboot,max (V) | Q14: =H6 -> 3.76
C15: =DB_GD[[#Headers],[Ihbs (mA)]] -> Ihbs (mA) | D15: =_xlfn.XLOOKUP(D9, DB_GD[Part], DB_GD[Ihbs (mA)]) -> 1.25 | J15: Cboot,min (nF) | K15: =K13/K14 -> 22.325465 | P15: =C6 -> Fmax (kHz) | Q15: =D6 -> 64
C16: =DB_GD[[#Headers],[Rboot,int (Ω)]] -> Rboot,int (Ω) | D16: =_xlfn.XLOOKUP(D9, DB_GD[Part], DB_GD[Rboot,int (Ω)]) -> 21.5 | G16: =G2 -> Vdd (V) | H16: =H2 -> 10.5 | P16: Pboot (mW) | Q16: =0.5*Q12*(1-Q13%)*Q14^2*Q15*10^-3 -> 57.002803
C17: Cboot | G17: =G5 -> Vf (V) | H17: =H5 -> 0.24
C18: =HMI!E16 -> Expected derating max (%) | D18: =HMI!F16 -> 60 | G18: Vboot,max (V) | H18: =H16-H17 -> 10.26 | M18: =C27 -> Rboot,ext (Ω) | N18: =D27 -> 3.3
C19: =HMI!E17 -> Expected derating min (%) | D19: =HMI!F17 -> 30 | M19: =C16 -> Rboot,int (Ω) | N19: =D16 -> 21.5
C20: =HMI!E18 -> Safety margin on Cboot | D20: =HMI!F18 -> 3 | J20: Basic JLCPCB capacitances | M20: Req (Ω) | N20: =N19*N18/(N18+N19) -> 2.8608871 | P20: =C27 -> Rboot,ext (Ω) | Q20: =D27 -> 3.3
C21: Dext,boot | J21: 47 | P21: =C16 -> Rboot,int (Ω) | Q21: =D16 -> 21.5
C22: Ref | D22: =HMI!E8 -> Rohm RB161QS-40 | G22: =G18 -> Vboot,max (V) | H22: =H18 -> 10.26 | J22: 56 | P22: =P16 -> Pboot (mW) | Q22: =Q16 -> 57.002803
C23: =DB_diode[[#Headers],[Vf@100mA (V)]] -> Vf@100mA (V) | D23: =_xlfn.XLOOKUP(D22, DB_diode[Ref], DB_diode[Vf@100mA (V)]) -> 0.24 | G23: =C25 -> Rpd,gate (kΩ) | H23: =D25 -> 10 | J23: 68 | P23: Prboot (mW) | Q23: =Q21/(Q20+Q21)*Q22 -> 49.417753
C24: Rpull-down,gate | G24: Ipd (mA) | H24: =H22/H23 -> 1.026 | J24: 82
C25: =HMI!E12 -> Rpd,gate (kΩ) | D25: =HMI!F12 -> 10 | J25: 100
C26: Rboot,ext | J26: 120
C27: =HMI!E19 -> Rboot,ext (Ω) | D27: =HMI!F19 -> 3.3 | J27: 150
C28: MOSFET | J28: 180
C29: Ref | D29: =HMI!H4 -> TI CSD18540Q5B | J29: 220
C30: =HMI!H6 -> Qg,typ @ 10V (nC) | D30: =_xlfn.XLOOKUP(D29, DB_Mostfet[Part],DB_Mostfet[Qg,typ @ 10V (nC)]) -> 41 | J30: 470
J31: 680
J32: 1000

Sheet CAL_Fets
G2: =C6 -> Iph mean (A) | H2: =D6 -> 12.905
C3: LIMITS | G3: =C7 -> Iph max (A@Xs) @ 4.9% ToF | H3: =D7 -> 20
C4: Name | D4: =HMI!B4 -> V1.0 | G4: =C13 -> Rds,on@10V max (mΩ) | H4: =D13 -> 2.2
C5: =HMI!B9 -> Vbat,typ (V) | D5: =HMI!C9 -> 25.2 | G5: =C9 -> Dmax (%) | H5: =D9 -> 90
C6: =HMI!B17 -> Iph mean (A) | D6: =_xlfn.XLOOKUP(D4,DB_limits[Name],DB_limits[Iph mean (A)]) -> 12.905 | G6: Pcond,mean (mW) | H6: =H2^2*H4*H5% -> 329.74727
C7: =HMI!B15 -> Iph max (A@Xs) @ 4.9% ToF | D7: =_xlfn.XLOOKUP(D4,DB_limits[Name],DB_limits[Iph max (A@Xs)]) -> 20 | G7: Pcond,max (mW) | H7: =H3^2*H4*H5% -> 792
C8: =HMI!B12 -> Vph spike (V) @ run | D8: =_xlfn.XLOOKUP(D4,DB_limits[Name],DB_limits[Vph spike (V) @ run]) -> 35
C9: =HMI!B6 -> Dmax (%) | D9: =_xlfn.XLOOKUP(D4,DB_limits[Name],DB_limits[Dmax (%)]) -> 90
C10: =HMI!B7 -> Fmax (kHz) | D10: =HMI!C7 -> 64
C11: =HMI!H2 -> MOSFET
C12: =DB_Mostfet[[#Headers],[Part]] -> Part | D12: =HMI!H4 -> TI CSD18540Q5B | G12: =C8 -> Vph spike (V) @ run | H12: =D8 -> 35
C13: =DB_Mostfet[[#Headers],[Rds,on@10V max (mΩ)]] -> Rds,on@10V max (mΩ) | D13: =_xlfn.XLOOKUP(D12, DB_Mostfet[Part], DB_Mostfet[Rds,on@10V max (mΩ)]) -> 2.2 | G13: =C6 -> Iph mean (A) | H13: =D6 -> 12.905
C14: Gate driving | G14: =C7 -> Iph max (A@Xs) @ 4.9% ToF | H14: =D7 -> 20
C15: =HMI!E37 -> t_rise (ns) | D15: =HMI!F37 -> 9.8825 | G15: =C10 -> Fmax (kHz) | H15: =D10 -> 64
C16: =HMI!E38 -> t_fall (ns) | D16: =HMI!F38 -> 7.54789 | G16: =C15 -> t_rise (ns) | H16: =D15 -> 9.8825
G17: =C16 -> t_fall (ns) | H17: =D16 -> 7.54789
G18: Psw,typ (mW) | H18: =0.5*H12*H13*H15*(H16+H17)*10^-3 -> 251.93189
G19: Psw,max (mW) | H19: =0.5*H12*H14*H15*(H16+H17)*10^-3 -> 390.44074
G24: =G6 -> Pcond,mean (mW) | H24: =H6 -> 329.74727
G25: =G7 -> Pcond,max (mW) | H25: =H7 -> 792
G26: =G18 -> Psw,typ (mW) | H26: =H18 -> 251.93189
G27: =G19 -> Psw,max (mW) | H27: =H19 -> 390.44074
G28: Ptot,typ (mW) | H28: =2*H24+4*H26 -> 1667.2221
G29: Ptot,max (mW) | H29: =2*H25+4*H27 -> 3145.7629

Sheet CAL_Rg
G2: =C8 -> Rg,off (Ω) | H2: =D8 -> 10 | J2: =C16 -> Vboot,max (V) | K2: =D16 -> 10.26 | M2: =C21 -> Qg,typ @ 10V (nC) | N2: =D21 -> 41 | P2: =M28 -> Rg,mean (Ω) | Q2: =N28 -> 1.6090602
C3: LIMITS | G3: =C9 -> Rg,on+off (Ω) | H3: =D9 -> 3.3 | J3: =G13 -> Req,on (Ω) | K3: =H13 -> 5.9 | M3: =C16 -> Vboot,max (V) | N3: =D16 -> 10.26 | P3: =M20 -> Rgatedriver,mean (Ω) | Q3: =N20 -> 0.47125
C4: Name | D4: =HMI!B4 -> V1.0 | G4: Rg,eq,off | H4: =H2*H3/(H3+H2) -> 2.481203 | J4: =G22 -> Req,off (Ω) | K4: =H22 -> 4.506203 | M4: =C6 -> Fmax (kHz) | N4: =D6 -> 64 | P4: =M11 -> Pg,loss (mW) | Q4: =N11 -> 40.38336
C5: =HMI!B6 -> Dmax (%) | D5: =HMI!C6 -> 90 | J5: Ig,max,on (A) | K5: =K2/K3 -> 1.7389831 | M5: Pg,loss,min (mW) | N5: =N2*N3*N4*10^-3 -> 26.92224 | P5: Prg,mean (mW) | Q5: =Q4*Q2/(Q2+Q3) -> 31.235369
C6: =HMI!B7 -> Fmax (kHz) | D6: =HMI!C7 -> 64 | J6: Ig,max,off (A) | K6: =K2/K4 -> 2.2768615
C7: GATE RESISTOR
C8: =HMI!E32 -> Rg,off (Ω) | D8: =HMI!F32 -> 10
C9: =HMI!E31 -> Rg,on+off (Ω) | D9: =HMI!F31 -> 3.3 | G9: =C12 -> Rpu,hs (Ω) | H9: =D12 -> 1 | M9: =M5 -> Pg,loss,min (mW) | N9: =N5 -> 26.92224
C10: GATE DRIVER | G10: =C13 -> Rpu,ls (Ω) | H10: =D13 -> 1 | M10: =C18 -> Safety margin on losses | N10: =D18 -> 1.5 | P10: =C8 -> Rg,off (Ω) | Q10: =D8 -> 10
C11: Ref | D11: =HMI!E3 -> Infineon 2EDL8024 | G11: =C9 -> Rg,on+off (Ω) | H11: =D9 -> 3.3 | M11: Pg,loss (mW) | N11: =N9*N10 -> 40.38336 | P11: =C9 -> Rg,on+off (Ω) | Q11: =D9 -> 3.3
C12: =DB_GD[[#Headers],[Rpu,hs (Ω)]] -> Rpu,hs (Ω) | D12: =_xlfn.XLOOKUP(D11, DB_GD[Part], DB_GD[Rpu,hs (Ω)]) -> 1 | G12: =C24 -> Rg,int,max (Ω) | H12: =D24 -> 1.6 | J12: =C23 -> Vmiller (V) | K12: =D23 -> 4 | P12: =P5 -> Prg,mean (mW) | Q12: =Q5 -> 31.235369
C13: =DB_GD[[#Headers],[Rpu,ls (Ω)]] -> Rpu,ls (Ω) | D13: =_xlfn.XLOOKUP(D11, DB_GD[Part], DB_GD[Rpu,ls (Ω)]) -> 1 | G13: Req,on (Ω) | H13: =(H10+H9)/2+H11+H12 -> 5.9 | J13: =G13 -> Req,on (Ω) | K13: =H13 -> 5.9 | P13: Prg,on+off (mW) | Q13: =0.5*(1+Q10/(Q10+Q11))*Q12 -> 27.360304
C14: =DB_GD[[#Headers],[Rpd,hs (Ω)]] -> Rpd,hs (Ω) | D14: =_xlfn.XLOOKUP(D11, DB_GD[Part], DB_GD[Rpd,hs (Ω)]) -> 0.5 | J14: =G22 -> Req,off (Ω) | K14: =H22 -> 4.506203
C15: =DB_GD[[#Headers],[Rpd,ls (Ω)]] -> Rpd,ls (Ω) | D15: =_xlfn.XLOOKUP(D11, DB_GD[Part], DB_GD[Rpd,ls (Ω)]) -> 0.35 | J15: Imiller,on (A) | K15: =K12/K13 -> 0.6779661 | M15: =C5 -> Dmax (%) | N15: =D5 -> 90
C16: =HMI!E22 -> Vboot,max (V) | D16: =HMI!F22 -> 10.26 | J16: Imiller,off (A) | K16: =K12/K14 -> 0.88766529 | M16: =G9 -> Rpu,hs (Ω) | N16: =H9 -> 1
C17: =HMI!E24 -> Cboot (nF) | D17: =HMI!F24 -> 180 | M17: =G10 -> Rpu,ls (Ω) | N17: =H10 -> 1
C18: =HMI!E33 -> Safety margin on losses | D18: =HMI!F33 -> 1.5 | G18: =C14 -> Rpd,hs (Ω) | H18: =D14 -> 0.5 | M18: =G18 -> Rpd,hs (Ω) | N18: =H18 -> 0.5 | P18: =P5 -> Prg,mean (mW) | Q18: =Q5 -> 31.235369
C19: MOSFET | G19: =C15 -> Rpd,ls (Ω) | H19: =D15 -> 0.35 | M19: =G19 -> Rpd,ls (Ω) | N19: =H19 -> 0.35 | P19: =P13 -> Prg,on+off (mW) | Q19: =Q13 -> 27.360304
C20: Ref | D20: =HMI!H4 -> TI CSD18540Q5B | G20: =G4 -> Rg,eq,off | H20: =H4 -> 2.481203 | M20: Rgatedriver,mean (Ω) | N20: =(N15%*(N17+N16)+(1-N15%)*(N18+N19))/4 -> 0.47125 | P20: Prg,off (mW) | Q20: =Q18-Q19 -> 3.8750646
C21: =DB_Mostfet[[#Headers],[Qg,typ @ 10V (nC)]] -> Qg,typ @ 10V (nC) | D21: =_xlfn.XLOOKUP(D20, DB_Mostfet[Part],DB_Mostfet[Qg,typ @ 10V (nC)]) -> 41 | G21: =C24 -> Rg,int,max (Ω) | H21: =D24 -> 1.6
C22: =DB_Mostfet[[#Headers],[Qgd,typ (nC)]] -> Qgd,typ (nC) | D22: =_xlfn.XLOOKUP(D20, DB_Mostfet[Part],DB_Mostfet[Qgd,typ (nC)]) -> 6.7 | G22: Req,off (Ω) | H22: =(H18+H19)/2+H20+H21 -> 4.506203 | J22: =C22 -> Qgd,typ (nC) | K22: =D22 -> 6.7
C23: =DB_Mostfet[[#Headers],[Vmiller (V)]] -> Vmiller (V) | D23: =_xlfn.XLOOKUP(D20, DB_Mostfet[Part],DB_Mostfet[Vmiller (V)]) -> 4 | J23: =J15 -> Imiller,on (A) | K23: =K15 -> 0.6779661
C24: =DB_Mostfet[[#Headers],[Rg,int,max (Ω)]] -> Rg,int,max (Ω) | D24: =_xlfn.XLOOKUP(D20, DB_Mostfet[Part],DB_Mostfet[Rg,int,max (Ω)]) -> 1.6 | J24: =J16 -> Imiller,off (A) | K24: =K16 -> 0.88766529 | P24: =M11 -> Pg,loss (mW) | Q24: =N11 -> 40.38336
J25: t_rise (ns) | K25: =K22/K23 -> 9.8825 | M25: =M15 -> Dmax (%) | N25: =N15 -> 90 | P25: =P5 -> Prg,mean (mW) | Q25: =Q5 -> 31.235369
J26: t_fall (ns) | K26: =K22/K24 -> 7.54789 | M26: =G3 -> Rg,on+off (Ω) | N26: =H3 -> 3.3 | P26: Prgdint,mean (mW) | Q26: =Q24-Q25 -> 9.1479909
M27: =G4 -> Rg,eq,off | N27: =H4 -> 2.481203
M28: Rg,mean (Ω) | N28: =(N25%*N26+(1-N25%)*N27)/2 -> 1.6090602

Sheet CAL_VSENSE
B2: Physic analysis of the Vsensing | M2: =HMI!B13 -> Vph spike (V) @ disarm | N2: =HMI!C13 -> 28 | O2: V | Q2: ADC resolution | R2: =HMI!U11 -> 0 | S2: bit
B3: R1 (kOhm) | C3: R2 (kOhm) | D3: Rth (kOhm) | E3: Ino (mA) | F3: S*RCint (ns) | G3: S*RCext (ns) | H3: F_filtered(MHz) | I3: Ptherm (mW) | J3: Increase 2520m (°C) | K3: Increase 2012m (°C) | M3: =HMI!B9 -> Vbat,typ (V) | N3: =HMI!C9 -> 25.2 | O3: V | Q3: ADC resolution | R3: =2^R2 -> 1 | S3: steps
B4: 0.1 | C4: =B4/$N$5 -> #DIV/0! | D4: =B4*C4/(B4+C4)+$N$17/1000 -> #DIV/0! | E4: =$N$4/D4 -> #DIV/0! | F4: =IF($N$9=0,$N$23*($N$8+$N$7)*D4,$N$23*(0.01)*$N$7) -> #N/A | G4: =$N$9*(D4+$N$17/1000)*$N$14 -> #DIV/0! | H4: =1/(2*PI()*($N$8+$N$7+$N$9)*D4)*1000 -> #N/A | I4: =$N$3*$N$3/(C4+B4) -> #DIV/0! | J4: =I4*$R$10/1000 -> #DIV/0! | K4: =I4*$R$11/1000 -> #DIV/0! | M4: Aimed Vth@45V | N4: =HMI!U5 -> 0 | O4: V | Q4: ADC resolution | R4: =N2/R3 -> 28 | S4: V/step
B5: 0.2 | C5: =B5/$N$5 -> #DIV/0! | D5: =B5*C5/(B5+C5)+$N$17/1000 -> #DIV/0! | E5: =$N$4/D5 -> #DIV/0! | F5: =IF($N$9=0,$N$23*($N$8+$N$7)*D5,$N$23*(0.1)*$N$7) -> #N/A | G5: =$N$9*(D5+$N$17/1000)*$N$14 -> #DIV/0! | H5: =1/(2*PI()*($N$8+$N$7+$N$9)*D5)*1000 -> #N/A | I5: =$N$3*$N$3/(C5+B5) -> #DIV/0! | J5: =I5*$R$10/1000 -> #DIV/0! | K5: =I5*$R$11/1000 -> #DIV/0! | M5: R1/R2 | N5: =N4/(N2-N4) -> 0 | O5: N/U | Q5: ADC usefull steps | R5: =N3/R4 -> 0.9 | S5: steps
B6: 0.3 | C6: =B6/$N$5 -> #DIV/0! | D6: =B6*C6/(B6+C6)+$N$17/1000 -> #DIV/0! | E6: =$N$4/D6 -> #DIV/0! | F6: =IF($N$9=0,$N$23*($N$8+$N$7)*D6,$N$23*(0.1)*$N$7) -> #N/A | G6: =$N$9*(D6+$N$17/1000)*$N$14 -> #DIV/0! | H6: =1/(2*PI()*($N$8+$N$7+$N$9)*D6)*1000 -> #N/A | I6: =$N$3*$N$3/(C6+B6) -> #DIV/0! | J6: =I6*$R$10/1000 -> #DIV/0! | K6: =I6*$R$11/1000 -> #DIV/0! | Q6: ADC sampling time | R6: =N22 -> #DIV/0! | S6: ns
B7: 0.4 | C7: =B7/$N$5 -> #DIV/0! | D7: =B7*C7/(B7+C7)+$N$17/1000 -> #DIV/0! | E7: =$N$4/D7 -> #DIV/0! | F7: =IF($N$9=0,$N$23*($N$8+$N$7)*D7,$N$23*(0.1)*$N$7) -> #N/A | G7: =$N$9*(D7+$N$17/1000)*$N$14 -> #DIV/0! | H7: =1/(2*PI()*($N$8+$N$7+$N$9)*D7)*1000 -> #N/A | I7: =$N$3*$N$3/(C7+B7) -> #DIV/0! | J7: =I7*$R$10/1000 -> #DIV/0! | K7: =I7*$R$11/1000 -> #DIV/0! | M7: Cadc | N7: =_xlfn.XLOOKUP(HMI!T4, DB_ADC[Name], DB_ADC[Vmax (V)]) -> #N/A | O7: pF | Q7: ADC conversion time | R7: =R2/N21*1000 -> #DIV/0! | S7: ns
B8: 0.5 | C8: =B8/$N$5 -> #DIV/0! | D8: =B8*C8/(B8+C8)+$N$17/1000 -> #DIV/0! | E8: =$N$4/D8 -> #DIV/0! | F8: =IF($N$9=0,$N$23*($N$8+$N$7)*D8,$N$23*(0.1)*$N$7) -> #N/A | G8: =$N$9*(D8+$N$17/1000)*$N$14 -> #DIV/0! | H8: =1/(2*PI()*($N$8+$N$7+$N$9)*D8)*1000 -> #N/A | I8: =$N$3*$N$3/(C8+B8) -> #DIV/0! | J8: =I8*$R$10/1000 -> #DIV/0! | K8: =I8*$R$11/1000 -> #DIV/0! | M8: Ctrace | N8: 0 | O8: pF | Q8: ADC total time | R8: =R7+R6 -> #DIV/0! | S8: ns
B9: 0.6 | C9: =B9/$N$5 -> #DIV/0! | D9: =B9*C9/(B9+C9)+$N$17/1000 -> #DIV/0! | E9: =$N$4/D9 -> #DIV/0! | F9: =IF($N$9=0,$N$23*($N$8+$N$7)*D9,$N$23*(0.1)*$N$7) -> #N/A | G9: =$N$9*(D9+$N$17/1000)*$N$14 -> #DIV/0! | H9: =1/(2*PI()*($N$8+$N$7+$N$9)*D9)*1000 -> #N/A | I9: =$N$3*$N$3/(C9+B9) -> #DIV/0! | J9: =I9*$R$10/1000 -> #DIV/0! | K9: =I9*$R$11/1000 -> #DIV/0! | M9: Cin_adc (0 is an option) | N9: =HMI!U20 -> 0 | O9: pF
B10: 0.7 | C10: =B10/$N$5 -> #DIV/0! | D10: =B10*C10/(B10+C10)+$N$17/1000 -> #DIV/0! | E10: =$N$4/D10 -> #DIV/0! | F10: =IF($N$9=0,$N$23*($N$8+$N$7)*D10,$N$23*(0.1)*$N$7) -> #N/A | G10: =$N$9*(D10+$N$17/1000)*$N$14 -> #DIV/0! | H10: =1/(2*PI()*($N$8+$N$7+$N$9)*D10)*1000 -> #N/A | I10: =$N$3*$N$3/(C10+B10) -> #DIV/0! | J10: =I10*$R$10/1000 -> #DIV/0! | K10: =I10*$R$11/1000 -> #DIV/0! | M10: Highest frequency (Fmax) | N10: =HMI!C7 -> 64 | O10: kHz | Q10: thermal resistance 2520m | R10: 80 | S10: °C/W
B11: 0.8 | C11: =B11/$N$5 -> #DIV/0! | D11: =B11*C11/(B11+C11)+$N$17/1000 -> #DIV/0! | E11: =$N$4/D11 -> #DIV/0! | F11: =IF($N$9=0,$N$23*($N$8+$N$7)*D11,$N$23*(0.1)*$N$7) -> #N/A | G11: =$N$9*(D11+$N$17/1000)*$N$14 -> #DIV/0! | H11: =1/(2*PI()*($N$8+$N$7+$N$9)*D11)*1000 -> #N/A | I11: =$N$3*$N$3/(C11+B11) -> #DIV/0! | J11: =I11*$R$10/1000 -> #DIV/0! | K11: =I11*$R$11/1000 -> #DIV/0! | M11: security on freq (f) | N11: 5 | O11: N/U | Q11: thermal resistance 2012m | R11: 150 | S11: °C/W
B12: 0.9 | C12: =B12/$N$5 -> #DIV/0! | D12: =B12*C12/(B12+C12)+$N$17/1000 -> #DIV/0! | E12: =$N$4/D12 -> #DIV/0! | F12: =IF($N$9=0,$N$23*($N$8+$N$7)*D12,$N$23*(0.1)*$N$7) -> #N/A | G12: =$N$9*(D12+$N$17/1000)*$N$14 -> #DIV/0! | H12: =1/(2*PI()*($N$8+$N$7+$N$9)*D12)*1000 -> #N/A | I12: =$N$3*$N$3/(C12+B12) -> #DIV/0! | J12: =I12*$R$10/1000 -> #DIV/0! | K12: =I12*$R$11/1000 -> #DIV/0! | M12: Amplitude error | N12: =(1-1/SQRT(1+(N10/N11/N10)^2))*100 -> 1.9419324 | O12: % | Q12: Ambient temp | R12: 80 | S12: °C
B13: 1 | C13: =B13/$N$5 -> #DIV/0! | D13: =B13*C13/(B13+C13)+$N$17/1000 -> #DIV/0! | E13: =$N$4/D13 -> #DIV/0! | F13: =IF($N$9=0,$N$23*($N$8+$N$7)*D13,$N$23*(0.1)*$N$7) -> #N/A | G13: =$N$9*(D13+$N$17/1000)*$N$14 -> #DIV/0! | H13: =1/(2*PI()*($N$8+$N$7+$N$9)*D13)*1000 -> #N/A | I13: =$N$3*$N$3/(C13+B13) -> #DIV/0! | J13: =I13*$R$10/1000 -> #DIV/0! | K13: =I13*$R$11/1000 -> #DIV/0! | M13: Phase error | N13: =ATAN(N10/N11/N10)/PI()*180 -> 11.309932 | O13: °
B14: 1.1 | C14: =B14/$N$5 -> #DIV/0! | D14: =B14*C14/(B14+C14)+$N$17/1000 -> #DIV/0! | E14: =$N$4/D14 -> #DIV/0! | F14: =IF($N$9=0,$N$23*($N$8+$N$7)*D14,$N$23*(0.1)*$N$7) -> #N/A | G14: =$N$9*(D14+$N$17/1000)*$N$14 -> #DIV/0! | H14: =1/(2*PI()*($N$8+$N$7+$N$9)*D14)*1000 -> #N/A | I14: =$N$3*$N$3/(C14+B14) -> #DIV/0! | J14: =I14*$R$10/1000 -> #DIV/0! | K14: =I14*$R$11/1000 -> #DIV/0! | M14: Charge factor (Sext) | N14: =N23 -> 0 | O14: N/U | Q14: To ensure a good feeding of the ADC
B15: 1.2 | C15: =B15/$N$5 -> #DIV/0! | D15: =B15*C15/(B15+C15)+$N$17/1000 -> #DIV/0! | E15: =$N$4/D15 -> #DIV/0! | F15: =IF($N$9=0,$N$23*($N$8+$N$7)*D15,$N$23*(0.1)*$N$7) -> #N/A | G15: =$N$9*(D15+$N$17/1000)*$N$14 -> #DIV/0! | H15: =1/(2*PI()*($N$8+$N$7+$N$9)*D15)*1000 -> #N/A | I15: =$N$3*$N$3/(C15+B15) -> #DIV/0! | J15: =I15*$R$10/1000 -> #DIV/0! | K15: =I15*$R$11/1000 -> #DIV/0! | M15: Allowed error | N15: =(EXP(-N14))*100 -> 100 | O15: % | Q15: sampling capacitance
B16: 1.3 | C16: =B16/$N$5 -> #DIV/0! | D16: =B16*C16/(B16+C16)+$N$17/1000 -> #DIV/0! | E16: =$N$4/D16 -> #DIV/0! | F16: =IF($N$9=0,$N$23*($N$8+$N$7)*D16,$N$23*(0.1)*$N$7) -> #N/A | G16: =$N$9*(D16+$N$17/1000)*$N$14 -> #DIV/0! | H16: =1/(2*PI()*($N$8+$N$7+$N$9)*D16)*1000 -> #N/A | I16: =$N$3*$N$3/(C16+B16) -> #DIV/0! | J16: =I16*$R$10/1000 -> #DIV/0! | K16: =I16*$R$11/1000 -> #DIV/0! | M16: Minimal blanking time | N16: =HMI!C20 -> 480 | O16: ns | Q16: tsamp > S*RC
B17: 1.4 | C17: =B17/$N$5 -> #DIV/0! | D17: =B17*C17/(B17+C17)+$N$17/1000 -> #DIV/0! | E17: =$N$4/D17 -> #DIV/0! | F17: =IF($N$9=0,$N$23*($N$8+$N$7)*D17,$N$23*(0.1)*$N$7) -> #N/A | G17: =$N$9*(D17+$N$17/1000)*$N$14 -> #DIV/0! | H17: =1/(2*PI()*($N$8+$N$7+$N$9)*D17)*1000 -> #N/A | I17: =$N$3*$N$3/(C17+B17) -> #DIV/0! | J17: =I17*$R$10/1000 -> #DIV/0! | K17: =I17*$R$11/1000 -> #DIV/0! | M17: Resistance on the ADC trace | N17: =Radc -> 0 | O17: Ohm
B18: 1.5 | C18: =B18/$N$5 -> #DIV/0! | D18: =B18*C18/(B18+C18)+$N$17/1000 -> #DIV/0! | E18: =$N$4/D18 -> #DIV/0! | F18: =IF($N$9=0,$N$23*($N$8+$N$7)*D18,$N$23*(0.1)*$N$7) -> #N/A | G18: =$N$9*(D18+$N$17/1000)*$N$14 -> #DIV/0! | H18: =1/(2*PI()*($N$8+$N$7+$N$9)*D18)*1000 -> #N/A | I18: =$N$3*$N$3/(C18+B18) -> #DIV/0! | J18: =I18*$R$10/1000 -> #DIV/0! | K18: =I18*$R$11/1000 -> #DIV/0! | Q18: We can note that, using a direct reading,
B19: 1.6 | C19: =B19/$N$5 -> #DIV/0! | D19: =B19*C19/(B19+C19)+$N$17/1000 -> #DIV/0! | E19: =$N$4/D19 -> #DIV/0! | F19: =IF($N$9=0,$N$23*($N$8+$N$7)*D19,$N$23*(0.1)*$N$7) -> #N/A | G19: =$N$9*(D19+$N$17/1000)*$N$14 -> #DIV/0! | H19: =1/(2*PI()*($N$8+$N$7+$N$9)*D19)*1000 -> #N/A | I19: =$N$3*$N$3/(C19+B19) -> #DIV/0! | J19: =I19*$R$10/1000 -> #DIV/0! | K19: =I19*$R$11/1000 -> #DIV/0! | M19: Only relevant if Cin_adc = 0 | Q19: it will be hard to have a quality reading on the
B20: 1.7 | C20: =B20/$N$5 -> #DIV/0! | D20: =B20*C20/(B20+C20)+$N$17/1000 -> #DIV/0! | E20: =$N$4/D20 -> #DIV/0! | F20: =IF($N$9=0,$N$23*($N$8+$N$7)*D20,$N$23*(0.1)*$N$7) -> #N/A | G20: =$N$9*(D20+$N$17/1000)*$N$14 -> #DIV/0! | H20: =1/(2*PI()*($N$8+$N$7+$N$9)*D20)*1000 -> #N/A | I20: =$N$3*$N$3/(C20+B20) -> #DIV/0! | J20: =I20*$R$10/1000 -> #DIV/0! | K20: =I20*$R$11/1000 -> #DIV/0! | M20: Nb cycles ADC | N20: =HMI!U10 -> 0 | O20: cycles | Q20: ADC with low power dissipation
B21: 1.8 | C21: =B21/$N$5 -> #DIV/0! | D21: =B21*C21/(B21+C21)+$N$17/1000 -> #DIV/0! | E21: =$N$4/D21 -> #DIV/0! | F21: =IF($N$9=0,$N$23*($N$8+$N$7)*D21,$N$23*(0.1)*$N$7) -> #N/A | G21: =$N$9*(D21+$N$17/1000)*$N$14 -> #DIV/0! | H21: =1/(2*PI()*($N$8+$N$7+$N$9)*D21)*1000 -> #N/A | I21: =$N$3*$N$3/(C21+B21) -> #DIV/0! | J21: =I21*$R$10/1000 -> #DIV/0! | K21: =I21*$R$11/1000 -> #DIV/0! | M21: Freq ADC | N21: =HMI!U8 -> 0 | O21: MHz
B22: 1.9 | C22: =B22/$N$5 -> #DIV/0! | D22: =B22*C22/(B22+C22)+$N$17/1000 -> #DIV/0! | E22: =$N$4/D22 -> #DIV/0! | F22: =IF($N$9=0,$N$23*($N$8+$N$7)*D22,$N$23*(0.1)*$N$7) -> #N/A | G22: =$N$9*(D22+$N$17/1000)*$N$14 -> #DIV/0! | H22: =1/(2*PI()*($N$8+$N$7+$N$9)*D22)*1000 -> #N/A | I22: =$N$3*$N$3/(C22+B22) -> #DIV/0! | J22: =I22*$R$10/1000 -> #DIV/0! | K22: =I22*$R$11/1000 -> #DIV/0! | M22: t sampling | N22: =N20/N21*1000 -> #DIV/0! | O22: ns
B23: 2 | C23: =B23/$N$5 -> #DIV/0! | D23: =B23*C23/(B23+C23)+$N$17/1000 -> #DIV/0! | E23: =$N$4/D23 -> #DIV/0! | F23: =IF($N$9=0,$N$23*($N$8+$N$7)*D23,$N$23*(0.1)*$N$7) -> #N/A | G23: =$N$9*(D23+$N$17/1000)*$N$14 -> #DIV/0! | H23: =1/(2*PI()*($N$8+$N$7+$N$9)*D23)*1000 -> #N/A | I23: =$N$3*$N$3/(C23+B23) -> #DIV/0! | J23: =I23*$R$10/1000 -> #DIV/0! | K23: =I23*$R$11/1000 -> #DIV/0! | M23: Charge factor (Sint) | N23: =HMI!U22 -> 0 | O23: N/U
B24: 3 | C24: =B24/$N$5 -> #DIV/0! | D24: =B24*C24/(B24+C24)+$N$17/1000 -> #DIV/0! | E24: =$N$4/D24 -> #DIV/0! | F24: =IF($N$9=0,$N$23*($N$8+$N$7)*D24,$N$23*(0.1)*$N$7) -> #N/A | G24: =$N$9*(D24+$N$17/1000)*$N$14 -> #DIV/0! | H24: =1/(2*PI()*($N$8+$N$7+$N$9)*D24)*1000 -> #N/A | I24: =$N$3*$N$3/(C24+B24) -> #DIV/0! | J24: =I24*$R$10/1000 -> #DIV/0! | K24: =I24*$R$11/1000 -> #DIV/0! | M24: Allowed error | N24: =(EXP(-N23))*100 -> 100 | O24: %
B25: 4 | C25: =B25/$N$5 -> #DIV/0! | D25: =B25*C25/(B25+C25)+$N$17/1000 -> #DIV/0! | E25: =$N$4/D25 -> #DIV/0! | F25: =IF($N$9=0,$N$23*($N$8+$N$7)*D25,$N$23*(0.1)*$N$7) -> #N/A | G25: =$N$9*(D25+$N$17/1000)*$N$14 -> #DIV/0! | H25: =1/(2*PI()*($N$8+$N$7+$N$9)*D25)*1000 -> #N/A | I25: =$N$3*$N$3/(C25+B25) -> #DIV/0! | J25: =I25*$R$10/1000 -> #DIV/0! | K25: =I25*$R$11/1000 -> #DIV/0! | M25: Allowed error | N25: =N24*R3/100 -> 1 | O25: steps
B26: 5 | C26: =B26/$N$5 -> #DIV/0! | D26: =B26*C26/(B26+C26)+$N$17/1000 -> #DIV/0! | E26: =$N$4/D26 -> #DIV/0! | F26: =IF($N$9=0,$N$23*($N$8+$N$7)*D26,$N$23*(0.1)*$N$7) -> #N/A | G26: =$N$9*(D26+$N$17/1000)*$N$14 -> #DIV/0! | H26: =1/(2*PI()*($N$8+$N$7+$N$9)*D26)*1000 -> #N/A | I26: =$N$3*$N$3/(C26+B26) -> #DIV/0! | J26: =I26*$R$10/1000 -> #DIV/0! | K26: =I26*$R$11/1000 -> #DIV/0! | M26: Allowed error | N26: =R4*N25*1000 -> 28000 | O26: mV
B27: 6 | C27: =B27/$N$5 -> #DIV/0! | D27: =B27*C27/(B27+C27)+$N$17/1000 -> #DIV/0! | E27: =$N$4/D27 -> #DIV/0! | F27: =IF($N$9=0,$N$23*($N$8+$N$7)*D27,$N$23*(0.1)*$N$7) -> #N/A | G27: =$N$9*(D27+$N$17/1000)*$N$14 -> #DIV/0! | H27: =1/(2*PI()*($N$8+$N$7+$N$9)*D27)*1000 -> #N/A | I27: =$N$3*$N$3/(C27+B27) -> #DIV/0! | J27: =I27*$R$10/1000 -> #DIV/0! | K27: =I27*$R$11/1000 -> #DIV/0! | M27: Real error (mean) | N27: =N26/N3 -> 1111.1111 | O27: %
B28: 7 | C28: =B28/$N$5 -> #DIV/0! | D28: =B28*C28/(B28+C28)+$N$17/1000 -> #DIV/0! | E28: =$N$4/D28 -> #DIV/0! | F28: =IF($N$9=0,$N$23*($N$8+$N$7)*D28,$N$23*(0.1)*$N$7) -> #N/A | G28: =$N$9*(D28+$N$17/1000)*$N$14 -> #DIV/0! | H28: =1/(2*PI()*($N$8+$N$7+$N$9)*D28)*1000 -> #N/A | I28: =$N$3*$N$3/(C28+B28) -> #DIV/0! | J28: =I28*$R$10/1000 -> #DIV/0! | K28: =I28*$R$11/1000 -> #DIV/0!
B29: 8 | C29: =B29/$N$5 -> #DIV/0! | D29: =B29*C29/(B29+C29)+$N$17/1000 -> #DIV/0! | E29: =$N$4/D29 -> #DIV/0! | F29: =IF($N$9=0,$N$23*($N$8+$N$7)*D29,$N$23*(0.1)*$N$7) -> #N/A | G29: =$N$9*(D29+$N$17/1000)*$N$14 -> #DIV/0! | H29: =1/(2*PI()*($N$8+$N$7+$N$9)*D29)*1000 -> #N/A | I29: =$N$3*$N$3/(C29+B29) -> #DIV/0! | J29: =I29*$R$10/1000 -> #DIV/0! | K29: =I29*$R$11/1000 -> #DIV/0! | M29: The whole ESC can dissipate up to 1.5W still and 3W with forced air
B30: 9 | C30: =B30/$N$5 -> #DIV/0! | D30: =B30*C30/(B30+C30)+$N$17/1000 -> #DIV/0! | E30: =$N$4/D30 -> #DIV/0! | F30: =IF($N$9=0,$N$23*($N$8+$N$7)*D30,$N$23*(0.1)*$N$7) -> #N/A | G30: =$N$9*(D30+$N$17/1000)*$N$14 -> #DIV/0! | H30: =1/(2*PI()*($N$8+$N$7+$N$9)*D30)*1000 -> #N/A | I30: =$N$3*$N$3/(C30+B30) -> #DIV/0! | J30: =I30*$R$10/1000 -> #DIV/0! | K30: =I30*$R$11/1000 -> #DIV/0!
B31: 10 | C31: =B31/$N$5 -> #DIV/0! | D31: =B31*C31/(B31+C31)+$N$17/1000 -> #DIV/0! | E31: =$N$4/D31 -> #DIV/0! | F31: =IF($N$9=0,$N$23*($N$8+$N$7)*D31,$N$23*(0.1)*$N$7) -> #N/A | G31: =$N$9*(D31+$N$17/1000)*$N$14 -> #DIV/0! | H31: =1/(2*PI()*($N$8+$N$7+$N$9)*D31)*1000 -> #N/A | I31: =$N$3*$N$3/(C31+B31) -> #DIV/0! | J31: =I31*$R$10/1000 -> #DIV/0! | K31: =I31*$R$11/1000 -> #DIV/0!
B32: 20 | C32: =B32/$N$5 -> #DIV/0! | D32: =B32*C32/(B32+C32)+$N$17/1000 -> #DIV/0! | E32: =$N$4/D32 -> #DIV/0! | F32: =IF($N$9=0,$N$23*($N$8+$N$7)*D32,$N$23*(0.1)*$N$7) -> #N/A | G32: =$N$9*(D32+$N$17/1000)*$N$14 -> #DIV/0! | H32: =1/(2*PI()*($N$8+$N$7+$N$9)*D32)*1000 -> #N/A | I32: =$N$3*$N$3/(C32+B32) -> #DIV/0! | J32: =I32*$R$10/1000 -> #DIV/0! | K32: =I32*$R$11/1000 -> #DIV/0!
B33: 0.39 | C33: =B33/$N$5 -> #DIV/0! | D33: =B33*C33/(B33+C33)+$N$17/1000 -> #DIV/0! | E33: =$N$4/D33 -> #DIV/0! | F33: =IF($N$9=0,$N$23*($N$8+$N$7)*D33,$N$23*(0.1)*$N$7) -> #N/A | G33: =$N$9*(D33+$N$17/1000)*$N$14 -> #DIV/0! | H33: =1/(2*PI()*($N$8+$N$7+$N$9)*D33)*1000 -> #N/A | I33: =$N$3*$N$3/(C33+B33) -> #DIV/0! | J33: =I33*$R$10/1000 -> #DIV/0! | K33: =I33*$R$11/1000 -> #DIV/0! | M33: =$N$2*B33/(C33+B33) -> #DIV/0!
B35: 0.39 | C35: 5.6 | D35: =B35*C35/(B35+C35)+$N$17/1000 -> 0.36460768 | E35: =$N$4/D35 -> 0 | F35: =IF($N$9=0,$N$23*($N$8+$N$7)*D35,$N$23*(0.1)*D35) -> #N/A | G35: =$N$9*(D35+$N$17/1000)*$N$14 -> 0 | H35: =1/(2*PI()*($N$8+$N$7+$N$9)*D35)*1000 -> #N/A | I35: =$N$3*$N$3/(C35+B35) -> 106.01669 | J35: =I35*$R$10/1000 -> 8.4813356 | K35: =I35*$R$11/1000 -> 15.902504 | M35: =$N$2*B35/(C35+B35) -> 1.8230384
F37: Ok if < tsample
H38: Ok if > Sf * Fmax
B41: Rbot (Ω) | C41: Rbot/Rtop | D41: Rtop (Ω) | E41: Rth (Ω) | F41: Iadc (mA) | G41: R_CinToAdc (Ω) | H41: S*RCint (ps)
B42: =HMI!U17 -> 0 | D42: =HMI!U18 -> 0 | E42: =CAL_Vsense[[#This Row],[Rtop (Ω)]]*CAL_Vsense[[#This Row],[Rbot (Ω)]]/(CAL_Vsense[[#This Row],[Rbot (Ω)]]+CAL_Vsense[[#This Row],[Rtop (Ω)]])+Radc -> #DIV/0! | F42: {=DB_ADC[Vref,adc (V)]/CAL_Vsense[[#This Row],[Rth (Ω)]]*1000} -> #DIV/0! | G42: {=HMI!U21*#REF!/1000} -> #REF! | H42: =HMI!U22*CAL_Vsense[[#This Row],[R_CinToAdc (Ω)]]*HMI!U21 -> #REF!

Sheet CAL_Rshunt
G2: =C11 -> Rshunt (µΩ) | H2: =D11 -> 850 | J2: =C16 -> Vref,adc (V) | K2: =D16 -> 3.3
C3: LIMITS | G3: =C5 -> Iph typ (A) @ 95% ToF | H3: =D5 -> 12.5 | J3: =C14 -> Resolution (bit) | K3: =D14 -> 12
C4: Name | D4: =HMI!B4 -> V1.0 | G4: Vshunt,typ (mV) | H4: =H3*H2/1000 -> 10.625 | J4: =G9 -> OpAmp gain | K4: =H9 -> 64
C5: =HMI!B14 -> Iph typ (A) @ 95% ToF | D5: =_xlfn.XLOOKUP(D4,DB_limits[Name],DB_limits[Iph typ (A)]) -> 12.5 | J5: =C11 -> Rshunt (µΩ) | K5: =D11 -> 850
C6: =HMI!B15 -> Iph max (A@Xs) @ 4.9% ToF | D6: =_xlfn.XLOOKUP(D4,DB_limits[Name],DB_limits[Iph max (A@Xs)]) -> 20 | J6: ΔIlsb (mA/bit) | K6: =K2/(2^K3-1)/K4/K5*10^9 -> 14.813618
C7: =HMI!B17 -> Iph mean (A) | D7: =_xlfn.XLOOKUP(D4,DB_limits[Name],DB_limits[Iph mean (A)]) -> 12.905
C8: =HMI!B16 -> Iph spike (A@Xms) @ 0.1% ToF | D8: =_xlfn.XLOOKUP(D4,DB_limits[Name],DB_limits[Iph spike (A@Xms)]) -> 50 | G8: =G4 -> Vshunt,typ (mV) | H8: =H4 -> 10.625
C9: =HMI!B6 -> Dmax (%) | D9: =_xlfn.XLOOKUP(D4,DB_limits[Name],DB_limits[Dmax (%)]) -> 90 | G9: =C15 -> OpAmp gain | H9: =D15 -> 64
C10: Rshunt | G10: Vshunt,amp,typ (V) | H10: =H9*H8/1000 -> 0.68
C11: =HMI!K4 -> Rshunt (µΩ) | D11: =HMI!L4 -> 850 | J11: =C11 -> Rshunt (µΩ) | K11: =D11 -> 850
C12: ADC & OpAmp | J12: =C7 -> Iph mean (A) | K12: =D7 -> 12.905
C13: =DB_ADC[[#Headers],[Name]] -> Name | D13: =HMI!K8 -> STM32G4 internal | J13: =C9 -> Dmax (%) | K13: =D9 -> 90
C14: =HMI!K11 -> Resolution (bit) | D14: =HMI!L11 -> 12 | G14: =C8 -> Iph spike (A@Xms) @ 0.1% ToF | H14: =D8 -> 50 | J14: Pshunt,mean (mW) | K14: =K11/10^3*K12^2*K13%*2/3 -> 84.934903
C15: =HMI!K13 -> OpAmp gain | D15: =HMI!L13 -> 64 | G15: =C11 -> Rshunt (µΩ) | H15: =D11 -> 850
C16: =DB_ADC[[#Headers],[Vref,adc (V)]] -> Vref,adc (V) | D16: =_xlfn.XLOOKUP(D13,DB_ADC[Name],DB_ADC[Vref,adc (V)]) -> 3.3 | G16: Vshunt,spike (mV) | H16: =H15*H14/1000 -> 42.5
J19: =J11 -> Rshunt (µΩ) | K19: =K11 -> 850
G20: =G16 -> Vshunt,spike (mV) | H20: =H16 -> 42.5 | J20: =C6 -> Iph max (A@Xs) @ 4.9% ToF | K20: =D6 -> 20
G21: =C15 -> OpAmp gain | H21: =D15 -> 64 | J21: =C9 -> Dmax (%) | K21: =D9 -> 90
G22: Vshunt,amp,spike (V) | H22: =H21*H20/1000 -> 2.72 | J22: Pshunt,max (mW@Xs) | K22: =K19/10^3*K20^2*K21%*2/3 -> 204

Sheet CAL_ISENSE_ARCH
B2: Physic analysis of the Isensing | I2: Minimal I to sens | J2: 0.01 | K2: A
B3: Rshunt (µOhm) | C3: Disspated power (W) | D3: Voltage drop spike amp (V) | E3: Voltage drop max amp (V) | F3: Voltage drop typ amp (V)2 | G3: mA/step | I3: Duty Cycle | J3: =HMI!C6 -> 90 | K3: %
B4: =0.1*1000 -> 100 | C4: =B4*$J$5*$J$5/1000/1000*$J$3/100 -> 0.036 | D4: =$J$6*B4/1000*$J$12/1000 -> 0 | E4: =$J$5*B4/1000*$J$12/1000 -> 0 | F4: =$J$4*B4/1000*$J$12/1000 -> 0 | G4: =$J$6/(D4/1000*$J$10/$J$8) -> #DIV/0! | I4: =HMI!B14 -> Iph typ (A) @ 95% ToF | J4: =HMI!C14 -> 12.5 | K4: A
B5: =B4+100 -> 200 | C5: =B5*$J$5*$J$5/1000/1000*$J$3/100 -> 0.072 | D5: =$J$6*B5/1000*$J$12/1000 -> 0 | E5: =$J$5*B5/1000*$J$12/1000 -> 0 | F5: =$J$4*B5/1000*$J$12/1000 -> 0 | G5: =$J$6/(D5/1000*$J$10/$J$8) -> #DIV/0! | I5: =HMI!B15 -> Iph max (A@Xs) @ 4.9% ToF | J5: =HMI!C15 -> 20 | K5: A
B6: 250 | C6: =B6*$J$5*$J$5/1000/1000*$J$3/100 -> 0.09 | D6: =$J$6*B6/1000*$J$12/1000 -> 0 | E6: =$J$5*B6/1000*$J$12/1000 -> 0 | F6: =$J$4*B6/1000*$J$12/1000 -> 0 | G6: =$J$6/(D6/1000*$J$10/$J$8) -> #DIV/0! | I6: =HMI!B16 -> Iph spike (A@Xms) @ 0.1% ToF | J6: =HMI!C16 -> 50 | K6: A
B7: =B5+100 -> 300 | C7: =B7*$J$5*$J$5/1000/1000*$J$3/100 -> 0.108 | D7: =$J$6*B7/1000*$J$12/1000 -> 0 | E7: =$J$5*B7/1000*$J$12/1000 -> 0 | F7: =$J$4*B7/1000*$J$12/1000 -> 0 | G7: =$J$6/(D7/1000*$J$10/$J$8) -> #DIV/0!
B8: =B7+100 -> 400 | C8: =B8*$J$5*$J$5/1000/1000*$J$3/100 -> 0.144 | D8: =$J$6*B8/1000*$J$12/1000 -> 0 | E8: =$J$5*B8/1000*$J$12/1000 -> 0 | F8: =$J$4*B8/1000*$J$12/1000 -> 0 | G8: =$J$6/(D8/1000*$J$10/$J$8) -> #DIV/0! | I8: ADC range | J8: =HMI!R5 -> 0 | K8: V
B9: =B8+100 -> 500 | C9: =B9*$J$5*$J$5/1000/1000*$J$3/100 -> 0.18 | D9: =$J$6*B9/1000*$J$12/1000 -> 0 | E9: =$J$5*B9/1000*$J$12/1000 -> 0 | F9: =$J$4*B9/1000*$J$12/1000 -> 0 | G9: =$J$6/(D9/1000*$J$10/$J$8) -> #DIV/0! | I9: ADC resolution | J9: =HMI!R11 -> 0 | K9: bit
B10: =B9+100 -> 600 | C10: =B10*$J$5*$J$5/1000/1000*$J$3/100 -> 0.216 | D10: =$J$6*B10/1000*$J$12/1000 -> 0 | E10: =$J$5*B10/1000*$J$12/1000 -> 0 | F10: =$J$4*B10/1000*$J$12/1000 -> 0 | G10: =$J$6/(D10/1000*$J$10/$J$8) -> #DIV/0! | I10: ADC resolution | J10: =2^J9 -> 1 | K10: steps
B11: =B10+100 -> 700 | C11: =B11*$J$5*$J$5/1000/1000*$J$3/100 -> 0.252 | D11: =$J$6*B11/1000*$J$12/1000 -> 0 | E11: =$J$5*B11/1000*$J$12/1000 -> 0 | F11: =$J$4*B11/1000*$J$12/1000 -> 0 | G11: =$J$6/(D11/1000*$J$10/$J$8) -> #DIV/0! | I11: ADC resolution | J11: =J8/J10*1000 -> 0 | K11: mV/s
B12: =B11+100 -> 800 | C12: =B12*$J$5*$J$5/1000/1000*$J$3/100 -> 0.288 | D12: =$J$6*B12/1000*$J$12/1000 -> 0 | E12: =$J$5*B12/1000*$J$12/1000 -> 0 | F12: =$J$4*B12/1000*$J$12/1000 -> 0 | G12: =$J$6/(D12/1000*$J$10/$J$8) -> #DIV/0! | I12: OPAMP gain | J12: =HMI!R12 -> 0 | K12: N/U
B13: =B12+100 -> 900 | C13: =B13*$J$5*$J$5/1000/1000*$J$3/100 -> 0.324 | D13: =$J$6*B13/1000*$J$12/1000 -> 0 | E13: =$J$5*B13/1000*$J$12/1000 -> 0 | F13: =$J$4*B13/1000*$J$12/1000 -> 0 | G13: =$J$6/(D13/1000*$J$10/$J$8) -> #DIV/0!
B14: =B13+100 -> 1000 | C14: =B14*$J$5*$J$5/1000/1000*$J$3/100 -> 0.36 | D14: =$J$6*B14/1000*$J$12/1000 -> 0 | E14: =$J$5*B14/1000*$J$12/1000 -> 0 | F14: =$J$4*B14/1000*$J$12/1000 -> 0 | G14: =$J$6/(D14/1000*$J$10/$J$8) -> #DIV/0!

Sheet CAL_Rv1-2
G2: =C18 -> Rv2 (Ω) | H2: =D18 -> 1000 | J2: =C6 -> Vbat,typ (V) | K2: =D6 -> 25.2 | M2: =G6 -> Rv1 (Ω) | N2: =H6 -> 10000 | P2: =C13 -> Csamp (pF) | Q2: =D13 -> 5
C3: LIMITS | G3: =C5 -> Vph spike (V) @ run | H3: =D5 -> 35 | J3: =G6 -> Rv1 (Ω) | K3: =H6 -> 10000 | M3: =C18 -> Rv2 (Ω) | N3: =D18 -> 1000 | P3: =C14 -> Cpad (pF) | Q3: =D14 -> 5
C4: Name | D4: =HMI!B4 -> V1.0 | G4: =C9 -> Vref,adc (V) | H4: =D9 -> 3.3 | J4: =C18 -> Rv2 (Ω) | K4: =D18 -> 1000 | M4: Rthvn (Ω) | N4: =N2*N3/(N3+N2) -> 909.09091 | P4: =C15 -> Ctrace,est (pF) | Q4: =D15 -> 5
C5: =HMI!B12 -> Vph spike (V) @ run | D5: =HMI!C12 -> 35 | G5: Rv1,th (Ω) | H5: =H2*(H3/H4-1) -> 9606.0606 | J5: Idivider,typ (mA) | K5: =K2/(K3+K4)*10^3 -> 2.2909091 | P5: Cadc,tot (pF) | Q5: =Q4+Q3+Q2 -> 15
C6: =HMI!B9 -> Vbat,typ (V) | D6: =HMI!C9 -> 25.2 | G6: Rv1 (Ω) | H6: =_xlfn.MINIFS(DB_R[R (Ω)],DB_R[R (Ω)],">="&H5) -> 10000
C7: ADC & OpAmp
C8: =DB_ADC[[#Headers],[Name]] -> Name | D8: =HMI!N11 -> STM32G4 internal
C9: =DB_ADC[[#Headers],[Vref,adc (V)]] -> Vref,adc (V) | D9: =_xlfn.XLOOKUP(D8,DB_ADC[Name],DB_ADC[Vref,adc (V)]) -> 3.3 | P9: =C24 -> Charge factor (int) | Q9: =D24 -> 12
C10: =HMI!N15 -> Resolution (bit) | D10: =HMI!O15 -> 8 | J10: =G23 -> Vdivider,spike (V) | K10: =H23 -> 3.1818182 | P10: =M27 -> Rthvn (Ω) | Q10: =N27 -> 909.09091
C11: =DB_ADC[[#Headers],[Tadc,clock (ns)]] -> Tadc,clock (ns) | D11: =_xlfn.XLOOKUP(D8,DB_ADC[Name],DB_ADC[Tadc,clock (ns)]) -> 16.666667 | G11: =G6 -> Rv1 (Ω) | H11: =H6 -> 10000 | J11: =G24 -> Vdivider,typ (V) | K11: =H24 -> 2.2909091 | P11: =M28 -> Radc,ext (Ω) | Q11: =N28 -> 33
C12: =HMI!N16 -> Nsamp (cycle) | D12: =HMI!O16 -> 2.5 | G12: =C18 -> Rv2 (Ω) | H12: =D18 -> 1000 | J12: =C20 -> Radc,ext (Ω) | K12: =D20 -> 33 | M12: =M4 -> Rthvn (Ω) | N12: =N4 -> 909.09091 | P12: =P5 -> Cadc,tot (pF) | Q12: =Q5 -> 15
C13: =HMI!N12 -> Csamp (pF) | D13: =HMI!O12 -> 5 | G13: =C5 -> Vph spike (V) @ run | H13: =D5 -> 35 | J13: Imax-in,adc,spike (mA) | K13: =K10/K12*1000 -> 96.418733 | M13: =C20 -> Radc,ext (Ω) | N13: =D20 -> 33 | P13: Tfill,samp (ns) | Q13: =Q9*(Q10+Q11)*(Q12)*10^-3 -> 169.57636
C14: =DB_ADC[[#Headers],[Cpad (pF)]] -> Cpad (pF) | D14: =HMI!O13 -> 5 | G14: Prv1,rv2 (mW) | H14: =H13^2/(H11+H12)*1000 -> 111.36364 | J14: Imax-in,adc,typ (mA) | K14: =K11/K12*1000 -> 69.421488 | M14: =C22 -> Cadc,ext (pF) | N14: =D22 -> 100
C15: =HMI!N17 -> Ctrace,est (pF) | D15: =HMI!O17 -> 5 | M15: Fc,adc,ext (MHz) | N15: =1/2/PI()/(N12+N13)/N14/10^-6 -> 1.6893799
C16: =HMI!N2 -> Rv2 & Rtrace
C17: =HMI!N4 -> Rv2 name | D17: =HMI!O4 -> 1kΩ, 2012m
C18: Rv2 (Ω) | D18: =_xlfn.XLOOKUP(D17, DB_R[Description], DB_R[R (Ω)]) -> 1000
C19: =HMI!N6 -> Radc,ext name | D19: =HMI!O6 -> 33Ω, 2012m | G19: =G6 -> Rv1 (Ω) | H19: =H6 -> 10000
C20: Radc,ext (Ω) | D20: =_xlfn.XLOOKUP(D19, DB_R[Description], DB_R[R (Ω)]) -> 33 | G20: =C18 -> Rv2 (Ω) | H20: =D18 -> 1000 | M20: =C22 -> Cadc,ext (pF) | N20: =D22 -> 100
C21: Cadc,ext | G21: =C5 -> Vph spike (V) @ run | H21: =D5 -> 35 | J21: =G23 -> Vdivider,spike (V) | K21: =H23 -> 3.1818182 | M21: =C23 -> Expected derating (%) | N21: =D23 -> 40
C22: =HMI!N29 -> Cadc,ext (pF) | D22: =HMI!O29 -> 100 | G22: =C6 -> Vbat,typ (V) | H22: =D6 -> 25.2 | J22: =C9 -> Vref,adc (V) | K22: =D9 -> 3.3 | M22: Cadc,ext,real (pF) | N22: =N20*(1-N21%) -> 60
C23: =HMI!N30 -> Expected derating (%) | D23: =HMI!O30 -> 40 | G23: Vdivider,spike (V) | H23: =H20*H21/(H20+H19) -> 3.1818182 | J23: =C10 -> Resolution (bit) | K23: =D10 -> 8
C24: =HMI!N31 -> Charge factor (int) | D24: =HMI!O31 -> 12 | G24: Vdivider,typ (V) | H24: =H20*H22/(H20+H19) -> 2.2909091 | J24: =C5 -> Vph spike (V) @ run | K24: =D5 -> 35
C25: =HMI!N32 -> Charge factor (ext) | D25: =HMI!O32 -> 5 | J25: ΔVlsb,fullscale (mV/bit) | K25: =K22/K21/(2^K23-1)*K24*1000 -> 142.35294
M26: =C25 -> Charge factor (ext) | N26: =D25 -> 5
M27: =M12 -> Rthvn (Ω) | N27: =N12 -> 909.09091
M28: =M13 -> Radc,ext (Ω) | N28: =N13 -> 33
M29: =M22 -> Cadc,ext,real (pF) | N29: =N22 -> 60
M30: Tfill,adc,ext (ns) | N30: =N26*(N27+N28)*N29*10^-3 -> 282.62727

Sheet DB_LIMITS
A1: Name | B1: Frame size (") | C1: Dmax (%) | D1: Fmax (kHz) | E1: Fmin (kHz) | F1: Batt max (S) | G1: Batt min (S) | H1: Cell max (V) | I1: Cell typ (V) | J1: Cell min (V) | K1: Vbat,typ (V) | L1: Vbat,min (V) | M1: Vbat spike (V) @ run | N1: Vph spike (V) @ run | O1: Vbat spike (V) @ disarm | P1: Vph spike (V) @ disarm | Q1: Iph typ (A) | R1: ToF Iph typ (%) | S1: Iph max (A@Xs) | T1: ToF Iph max (%) | U1: Iph spike (A@Xms) | V1: ToF Iph spike (%) | W1: Iph mean (A) | X1: Termistors
A2: V1.0 | B2: 6 | C2: 90 | D2: 64 | E2: 24 | F2: 6 | G2: 4 | H2: 4.2 | I2: 3.7 | J2: 3.5 | K2: =H2*F2 -> 25.2 | L2: =J2*G2 -> 14 | M2: 32 | N2: 35 | O2: 45 | P2: 28 | Q2: 12.5 | R2: 95 | S2: 20 | T2: =100-DB_limits[[#This Row],[ToF Iph typ (%)]]-DB_limits[[#This Row],[ToF Iph spike (%)]] -> 4.9 | U2: 50 | V2: 0.1 | W2: =DB_limits[[#This Row],[Iph typ (A)]]*DB_limits[[#This Row],[ToF Iph typ (%)]]%+DB_limits[[#This Row],[Iph max (A@Xs)]]*DB_limits[[#This Row],[ToF Iph max (%)]]%+DB_limits[[#This Row],[Iph spike (A@Xms)]]*DB_limits[[#This Row],[ToF Iph spike (%)]]% -> 12.905 | X2: 3 (one at each FET)
A3: V1.0 (48kHz) | B3: 6 | C3: 90 | D3: 48 | E3: 24 | F3: 6 | G3: 4 | H3: 4.2 | I3: 3.7 | J3: 3.5 | K3: =H3*F3 -> 25.2 | L3: =J3*G3 -> 14 | M3: 32 | N3: 35 | O3: 45 | P3: 28 | Q3: 12.5 | R3: 95 | S3: 20 | T3: =100-DB_limits[[#This Row],[ToF Iph typ (%)]]-DB_limits[[#This Row],[ToF Iph spike (%)]] -> 4.9 | U3: 50 | V3: 0.1 | W3: =DB_limits[[#This Row],[Iph typ (A)]]*DB_limits[[#This Row],[ToF Iph typ (%)]]%+DB_limits[[#This Row],[Iph max (A@Xs)]]*DB_limits[[#This Row],[ToF Iph max (%)]]%+DB_limits[[#This Row],[Iph spike (A@Xms)]]*DB_limits[[#This Row],[ToF Iph spike (%)]]% -> 12.905 | X3: 3 (one at each FET)
A4: V1.0 (hard flight) | B4: 6 | C4: 90 | D4: 64 | E4: 24 | F4: 6 | G4: 4 | H4: 4.2 | I4: 3.7 | J4: 3.5 | K4: =H4*F4 -> 25.2 | L4: =J4*G4 -> 14 | M4: 32 | N4: 35 | O4: 45 | P4: 28 | Q4: 12.5 | R4: 85 | S4: 25 | T4: =100-DB_limits[[#This Row],[ToF Iph typ (%)]]-DB_limits[[#This Row],[ToF Iph spike (%)]] -> 14 | U4: 50 | V4: 1 | W4: =DB_limits[[#This Row],[Iph typ (A)]]*DB_limits[[#This Row],[ToF Iph typ (%)]]%+DB_limits[[#This Row],[Iph max (A@Xs)]]*DB_limits[[#This Row],[ToF Iph max (%)]]%+DB_limits[[#This Row],[Iph spike (A@Xms)]]*DB_limits[[#This Row],[ToF Iph spike (%)]]% -> 14.625 | X4: 3 (one at each FET)
A5: V1.0 (95%D) | B5: 6 | C5: 95 | D5: 64 | E5: 24 | F5: 6 | G5: 4 | H5: 4.2 | I5: 3.7 | J5: 3.5 | K5: =H5*F5 -> 25.2 | L5: =J5*G5 -> 14 | M5: 32 | N5: 35 | O5: 45 | P5: 28 | Q5: 12.5 | R5: 95 | S5: 20 | T5: =100-DB_limits[[#This Row],[ToF Iph typ (%)]]-DB_limits[[#This Row],[ToF Iph spike (%)]] -> 4.9 | U5: 50 | V5: 0.1 | W5: =DB_limits[[#This Row],[Iph typ (A)]]*DB_limits[[#This Row],[ToF Iph typ (%)]]%+DB_limits[[#This Row],[Iph max (A@Xs)]]*DB_limits[[#This Row],[ToF Iph max (%)]]%+DB_limits[[#This Row],[Iph spike (A@Xms)]]*DB_limits[[#This Row],[ToF Iph spike (%)]]% -> 12.905 | X5: 3 (one at each FET)
A6: V2.0 | B6: 6 | C6: 95 | D6: 96 | E6: 24 | F6: 6 | G6: 4 | H6: 4.2 | I6: 3.7 | J6: 3.25 | K6: =H6*F6 -> 25.2 | L6: =J6*G6 -> 13 | M6: 32 | N6: 35 | O6: 45 | P6: 28 | Q6: 15 | R6: 85 | S6: 25 | T6: =100-DB_limits[[#This Row],[ToF Iph typ (%)]]-DB_limits[[#This Row],[ToF Iph spike (%)]] -> 14 | U6: 60 | V6: 1 | W6: =DB_limits[[#This Row],[Iph typ (A)]]*DB_limits[[#This Row],[ToF Iph typ (%)]]%+DB_limits[[#This Row],[Iph max (A@Xs)]]*DB_limits[[#This Row],[ToF Iph max (%)]]%+DB_limits[[#This Row],[Iph spike (A@Xms)]]*DB_limits[[#This Row],[ToF Iph spike (%)]]% -> 16.85 | X6: 1 (at a FET)
A7: V1.0 (48kHz + hard flight) | B7: 6 | C7: 90 | D7: 64 | E7: 24 | F7: 6 | G7: 4 | H7: 4.2 | I7: 3.7 | J7: 3.5 | K7: =H7*F7 -> 25.2 | L7: =J7*G7 -> 14 | M7: 32 | N7: 35 | O7: 45 | P7: 28 | Q7: 12.5 | R7: 85 | S7: 25 | T7: =100-DB_limits[[#This Row],[ToF Iph typ (%)]]-DB_limits[[#This Row],[ToF Iph spike (%)]] -> 14 | U7: 50 | V7: 1 | W7: =DB_limits[[#This Row],[Iph typ (A)]]*DB_limits[[#This Row],[ToF Iph typ (%)]]%+DB_limits[[#This Row],[Iph max (A@Xs)]]*DB_limits[[#This Row],[ToF Iph max (%)]]%+DB_limits[[#This Row],[Iph spike (A@Xms)]]*DB_limits[[#This Row],[ToF Iph spike (%)]]% -> 14.625 | X7: 3 (one at each FET)

Sheet DB_GD
A1: Part | B1: Vhbr (V) | C1: Vhbh,max (V) | D1: Rboot,int (Ω) | E1: Ihb (mA) | F1: Ihbs (mA) | G1: Vout (V) | H1: Rpu,hs (Ω) | I1: Rpu,ls (Ω) | J1: Rpd,hs (Ω) | K1: Rpd,ls (Ω) | L1: Vfint,100mA (V)
A2: Infineon 2EDL8024 | B2: 6 | C2: 0.5 | D2: 21.5 | E2: 0.7 | F2: 1.25 | G2: 10 | H2: 1 | I2: 1 | J2: 0.5 | K2: 0.35 | L2: 2.15

Sheet DB_R
A1: Description | B1: R (Ω) | C1: R (kΩ) | D1: Prated@70°C (W) | E1: Package (inch) | F1: Package (m) | G1: Name | H1: Basic
A2: =IF(B2>=1000,C2& "kΩ, ",B2& "Ω, ") & DB_R[[#This Row],[Package (m)]] -> 10Ω, 2012m | B2: 10 | C2: =DB_R[[#This Row],[R (Ω)]]/1000 -> 0.01 | D2: 0.25 | E2: 0805 | F2: 2012m | H2: UKN
A3: =IF(B3>=1000,C3& "kΩ, ",B3& "Ω, ") & DB_R[[#This Row],[Package (m)]] -> 11Ω, 2012m | B3: 11 | C3: =DB_R[[#This Row],[R (Ω)]]/1000 -> 0.011 | D3: 0.25 | E3: 0805 | F3: 2012m | H3: UKN
A4: =IF(B4>=1000,C4& "kΩ, ",B4& "Ω, ") & DB_R[[#This Row],[Package (m)]] -> 12Ω, 2012m | B4: 12 | C4: =DB_R[[#This Row],[R (Ω)]]/1000 -> 0.012 | D4: 0.25 | E4: 0805 | F4: 2012m | H4: UKN
A5: =IF(B5>=1000,C5& "kΩ, ",B5& "Ω, ") & DB_R[[#This Row],[Package (m)]] -> 13Ω, 2012m | B5: 13 | C5: =DB_R[[#This Row],[R (Ω)]]/1000 -> 0.013 | D5: 0.25 | E5: 0805 | F5: 2012m | H5: UKN
A6: =IF(B6>=1000,C6& "kΩ, ",B6& "Ω, ") & DB_R[[#This Row],[Package (m)]] -> 15Ω, 2012m | B6: 15 | C6: =DB_R[[#This Row],[R (Ω)]]/1000 -> 0.015 | D6: 0.25 | E6: 0805 | F6: 2012m | H6: UKN
A7: =IF(B7>=1000,C7& "kΩ, ",B7& "Ω, ") & DB_R[[#This Row],[Package (m)]] -> 16Ω, 2012m | B7: 16 | C7: =DB_R[[#This Row],[R (Ω)]]/1000 -> 0.016 | D7: 0.25 | E7: 0805 | F7: 2012m | H7: UKN
A8: =IF(B8>=1000,C8& "kΩ, ",B8& "Ω, ") & DB_R[[#This Row],[Package (m)]] -> 18Ω, 2012m | B8: 18 | C8: =DB_R[[#This Row],[R (Ω)]]/1000 -> 0.018 | D8: 0.25 | E8: 0805 | F8: 2012m | H8: UKN
A9: =IF(B9>=1000,C9& "kΩ, ",B9& "Ω, ") & DB_R[[#This Row],[Package (m)]] -> 20Ω, 2012m | B9: 20 | C9: =DB_R[[#This Row],[R (Ω)]]/1000 -> 0.02 | D9: 0.25 | E9: 0805 | F9: 2012m | H9: UKN
A10: =IF(B10>=1000,C10& "kΩ, ",B10& "Ω, ") & DB_R[[#This Row],[Package (m)]] -> 22Ω, 2012m | B10: 22 | C10: =DB_R[[#This Row],[R (Ω)]]/1000 -> 0.022 | D10: 0.25 | E10: 0805 | F10: 2012m | H10: UKN
A11: =IF(B11>=1000,C11& "kΩ, ",B11& "Ω, ") & DB_R[[#This Row],[Package (m)]] -> 24Ω, 2012m | B11: 24 | C11: =DB_R[[#This Row],[R (Ω)]]/1000 -> 0.024 | D11: 0.25 | E11: 0805 | F11: 2012m | H11: UKN
A12: =IF(B12>=1000,C12& "kΩ, ",B12& "Ω, ") & DB_R[[#This Row],[Package (m)]] -> 27Ω, 2012m | B12: 27 | C12: =DB_R[[#This Row],[R (Ω)]]/1000 -> 0.027 | D12: 0.25 | E12: 0805 | F12: 2012m | H12: UKN
A13: =IF(B13>=1000,C13& "kΩ, ",B13& "Ω, ") & DB_R[[#This Row],[Package (m)]] -> 30Ω, 2012m | B13: 30 | C13: =DB_R[[#This Row],[R (Ω)]]/1000 -> 0.03 | D13: 0.25 | E13: 0805 | F13: 2012m | H13: UKN
... A71: =IF(B71>=1000,C71& "kΩ, ",B71& "Ω, ") & DB_R[[#This Row],[Package (m)]] -> 9.1kΩ, 2012m | B71: 9100 | C71: =DB_R[[#This Row],[R (Ω)]]/1000 -> 9.1 | D71: 0.25 | E71: 0805 | F71: 2012m | H71: UKN
A72: =IF(B72>=1000,C72& "kΩ, ",B72& "Ω, ") & DB_R[[#This Row],[Package (m)]] -> 10kΩ, | B72: 10000 | C72: =DB_R[[#This Row],[R (Ω)]]/1000 -> 10
A73: =IF(B73>=1000,C73& "kΩ, ",B73& "Ω, ") & DB_R[[#This Row],[Package (m)]] -> 10kΩ, | B73: 10000 | C73: =DB_R[[#This Row],[R (Ω)]]/1000 -> 10
A74: =IF(B74>=1000,C74& "kΩ, ",B74& "Ω, ") & DB_R[[#This Row],[Package (m)]] -> 11kΩ, | B74: 11000 | C74: =DB_R[[#This Row],[R (Ω)]]/1000 -> 11
A75: =IF(B75>=1000,C75& "kΩ, ",B75& "Ω, ") & DB_R[[#This Row],[Package (m)]] -> 12kΩ, | B75: 12000 | C75: =DB_R[[#This Row],[R (Ω)]]/1000 -> 12
A76: =IF(B76>=1000,C76& "kΩ, ",B76& "Ω, ") & DB_R[[#This Row],[Package (m)]] -> 13kΩ, | B76: 13000 | C76: =DB_R[[#This Row],[R (Ω)]]/1000 -> 13
A77: =IF(B77>=1000,C77& "kΩ, ",B77& "Ω, ") & DB_R[[#This Row],[Package (m)]] -> 15kΩ, | B77: 15000 | C77: =DB_R[[#This Row],[R (Ω)]]/1000 -> 15
A78: =IF(B78>=1000,C78& "kΩ, ",B78& "Ω, ") & DB_R[[#This Row],[Package (m)]] -> 16kΩ, | B78: 16000 | C78: =DB_R[[#This Row],[R (Ω)]]/1000 -> 16
A79: =IF(B79>=1000,C79& "kΩ, ",B79& "Ω, ") & DB_R[[#This Row],[Package (m)]] -> 18kΩ, | B79: 18000 | C79: =DB_R[[#This Row],[R (Ω)]]/1000 -> 18
A80: =IF(B80>=1000,C80& "kΩ, ",B80& "Ω, ") & DB_R[[#This Row],[Package (m)]] -> 20kΩ, | B80: 20000 | C80: =DB_R[[#This Row],[R (Ω)]]/1000 -> 20
A81: =IF(B81>=1000,C81& "kΩ, ",B81& "Ω, ") & DB_R[[#This Row],[Package (m)]] -> 22kΩ, | B81: 22000 | C81: =DB_R[[#This Row],[R (Ω)]]/1000 -> 22
A82: =IF(B82>=1000,C82& "kΩ, ",B82& "Ω, ") & DB_R[[#This Row],[Package (m)]] -> 24kΩ, | B82: 24000 | C82: =DB_R[[#This Row],[R (Ω)]]/1000 -> 24
A83: =IF(B83>=1000,C83& "kΩ, ",B83& "Ω, ") & DB_R[[#This Row],[Package (m)]] -> 27kΩ, | B83: 27000 | C83: =DB_R[[#This Row],[R (Ω)]]/1000 -> 27
... A97: =IF(B97>=1000,C97& "kΩ, ",B97& "Ω, ") & DB_R[[#This Row],[Package (m)]] -> 100kΩ, | B97: 100000 | C97: =DB_R[[#This Row],[R (Ω)]]/1000 -> 100

Sheet DB_D
A1: Ref | B1: Vf@100mA (V)
A2: Rohm RB161QS-40 | B2: 0.24

Sheet DB_FETS
A1: Part | B1: Manifacturer | C1: Vds (V) | D1: Rds,on@10V typ(mΩ) | E1: Rds,on@10V max (mΩ) | F1: Qg,typ @ 10V (nC) | G1: Qg,max @ 10V (nC) | H1: Qg,typ,sync @ 10V (nC) | I1: Id @ Tc=25°C (A) | J1: Id @ Tc>70°C (A) | K1: Id @ Ta=25°C (A) | L1: Id @ Ta>70°C (A) | M1: Id,pulsed (A) | N1: Rise time (ns) | O1: Fall time (ns) | P1: Size (mm) | Q1: Vmiller (V) | R1: Qgd,typ (nC) | S1: Rg,int,max (Ω) | T1: JLCPBC stock
A2: STL180N6F7 | B2: STM | C2: 60 | D2: 1.9 | E2: 2.4 | F2: 79.5 | G2: X | H2: X | I2: 120 | J2: 120 | K2: 32 | L2: 20 | M2: 128 | N2: 35.6 | O2: 42.2 | P2: 5x6 | T2: No
A3: NVMFS5C604NL | B3: Onsemi | C3: 60 | D3: 0.93 | E3: 1.2 | F3: 120 | G3: X | H3: X | I3: 287 | J3: 200 | K3: 40 | L3: 28 | M3: 900 | N3: 79.1 | O3: 81.3 | P3: 5x6 | T3: Yes
A4: TPN4R806PL | B4: Toshiba | C4: 60 | D4: 3.5 | E4: 4.8 | F4: 29 | G4: X | H4: X | I4: 72 | J4: 105 | K4: (est ~15) | L4: (est <15) | M4: 200 | N4: 4 | O4: 5.1 | P4: 3.3x3.3 | T4: No
A5: SiR186LDP | B5: Vishay | C5: 60 | D5: =0.0035*1000 -> 3.5 | E5: =0.0044*1000 -> 4.4 | F5: 31.5 | G5: X | H5: X | I5: 80.3 | J5: 64.2 | K5: 23.8 | L5: 19 | M5: 150 | N5: 6 | O5: 6 | P5: 5x6 | T5: Yes
A6: BSC027N06LS5 | B6: Infineon | C6: 60 | D6: 2.3 | E6: 2.7 | F6: 43 | G6: X | H6: X | I6: 134 | J6: 84 | K6: 23 | L6: (est ~13-15A) | M6: 536 | N6: 4.8 | O6: 5.4 | P6: 5x6 | T6: ~Yes
A7: BSC016N06NS | B7: Infineon | C7: 60 | D7: 1.4 | E7: 1.6 | F7: 71 | G7: 95 | H7: 62 | I7: 234 | J7: 164 | K7: 31 | L7: (est ~21A) | M7: 936 | N7: 9 | O7: 9 | P7: 5x6 | T7: Yes
A8: TI CSD18540Q5B | B8: TI | C8: 60 | D8: 1.8 | E8: 2.2 | F8: 41 | G8: 53 | H8: X | I8: 100 | J8: 100 | K8: 29 | L8: (est ~21A) | M8: 400 | N8: 9 | O8: 3 | P8: 5x6 | Q8: 4 | R8: 6.7 | S8: 1.6 | T8: Yes
N11: Depend of Rg | O11: Depend of Rg

Sheet DB_ADC
A1: Name | B1: Vref,adc (V) | C1: Vmax (V) | D1: Csamp (pF) | E1: Cpad (pF) | F1: Fadc,clock(MHz) | G1: Tadc,clock (ns) | H1: Vin,max@vin (V)
A2: STM32G4 internal | B2: 3.3 | C2: =DB_ADC[[#This Row],[Vref,adc (V)]]+0.3 -> 3.6 | D2: 5 | E2: 5 | F2: 60 | G2: =1/DB_ADC[[#This Row],[Fadc,clock(MHz)]]*10^3 -> 16.666667 | H2: =DB_ADC[[#This Row],[Vref,adc (V)]]+0.3 -> 3.6

Sheet Mosfet
B2: Drained current mean | C2: I_D | D2: 15 | E2: A
B3: Duty cycle | C3: D | D3: 95 | E3: %
B4: Drain-to-Source voltage | C4: V_DS | D4: 26 | E4: V
B5: Drain-to-Source electrical resistance | C5: R_DS,on | D5: 1.2 | E5: mΩ
B6: Rise time | C6: t_r | D6: 79 | E6: ns
B7: Fall time | C7: t_f | D7: 81 | E7: ns
B8: Switching frequency (PWM) | C8: f_pwm | D8: 64 | E8: kHz
B10: Conduction thermal losses max | C10: P_cond | D10: =D5/1000*D2^2*D3/100 -> 0.2565 | E10: W
B11: Switching thermal losses | C11: P_sw | D11: =1/2*D4*D2*(D6+D7)*D8/1000000 -> 1.9968 | E11: W
B12: Total thermal losses for ESC | C12: P_tot | D12: =D10*2+D11 -> 2.5098 | E12: W
B14: Rated for 64kHz without active cooling for v1
B15: Term goal is 128kHz but will require review of the gate resistor setup
B16: 95% duty is the goal for v1
